Workbook

Sheet produk
A1: id | B1: PRODUK
A2: =ROW()-1 -> 1 | B2: TK1401
A3: =ROW()-1 -> 2 | B3: TK1403
A4: =ROW()-1 -> 3 | B4: TK1608
A5: =ROW()-1 -> 4 | B5: TK1609
A6: =ROW()-1 -> 5 | B6: TK4909
A7: =ROW()-1 -> 6 | B7: TK5030
A8: =ROW()-1 -> 7 | B8: TK5037
A9: =ROW()-1 -> 8 | B9: TK5041
A10: =ROW()-1 -> 9 | B10: TK5047
A11: =ROW()-1 -> 10 | B11: TK5063A
A12: =ROW()-1 -> 11 | B12: TK5069
A13: =ROW()-1 -> 12 | B13: TK5070
... A119: =ROW()-1 -> 118 | B119: REWORK

Sheet jenis_pekerjaan
A1: id | B1: JENIS PEKERJAAN
A2: =ROW()-1 -> 1 | B2: PRESS
A3: =ROW()-1 -> 2 | B3: SANDER
A4: =ROW()-1 -> 3 | B4: SANDER AS
A5: =ROW()-1 -> 4 | B5: SANDER & WASHER
A6: =ROW()-1 -> 5 | B6: CHAMFER
A7: =ROW()-1 -> 6 | B7: CHAMFER 45
A8: =ROW()-1 -> 7 | B8: CHAMFER 25
A9: =ROW()-1 -> 8 | B9: CHAMFER 9
A10: =ROW()-1 -> 9 | B10: CHAMFER 10
A11: =ROW()-1 -> 10 | B11: CHAMFER 12
A12: =ROW()-1 -> 11 | B12: CHAMFER 22
A13: =ROW()-1 -> 12 | B13: CHAMFER OD
... A79: =ROW()-1 -> 78 | B79: T-SLOT CHAMFER

Sheet target
A1: PRODUK | B1: JENIS_PEKERJAAN | C1: TARGET | D1: fk_produk | E1: fk_jenis_pekerjaan | F1: CYCLE TIME (menit / pcs) | G1: PEMBULATAN CYCLE TIME (menit / pcs)
A2: TK1401 | B2: PRESS | C2: 5400 | D2: =_xlfn.XLOOKUP(A2, produk!$B:$B, produk!$A:$A) -> 1 | E2: =_xlfn.XLOOKUP(B2, jenis_pekerjaan!$B:$B, jenis_pekerjaan!$A:$A) -> 1 | F2: 0.07 | G2: =ROUNDDOWN(F2,2) -> 0.07
A3: TK1401 | B3: SANDER | C3: 4500 | D3: =_xlfn.XLOOKUP(A3, produk!$B:$B, produk!$A:$A) -> 1 | E3: =_xlfn.XLOOKUP(B3, jenis_pekerjaan!$B:$B, jenis_pekerjaan!$A:$A) -> 2 | F3: 0.084 | G3: =ROUNDDOWN(F3,2) -> 0.08
A4: TK1401 | B4: CHAMFER | C4: 2800 | D4: =_xlfn.XLOOKUP(A4, produk!$B:$B, produk!$A:$A) -> 1 | E4: =_xlfn.XLOOKUP(B4, jenis_pekerjaan!$B:$B, jenis_pekerjaan!$A:$A) -> 5 | F4: 0.135 | G4: =ROUNDDOWN(F4,2) -> 0.13
A5: TK1401 | B5: BUBUT | C5: 1250 | D5: =_xlfn.XLOOKUP(A5, produk!$B:$B, produk!$A:$A) -> 1 | E5: =_xlfn.XLOOKUP(B5, jenis_pekerjaan!$B:$B, jenis_pekerjaan!$A:$A) -> 16 | F5: 0.3024 | G5: =ROUNDDOWN(F5,2) -> 0.3
A6: TK1401 | B6: BRUSH | C6: 2800 | D6: =_xlfn.XLOOKUP(A6, produk!$B:$B, produk!$A:$A) -> 1 | E6: =_xlfn.XLOOKUP(B6, jenis_pekerjaan!$B:$B, jenis_pekerjaan!$A:$A) -> 19 | F6: 0.135 | G6: =ROUNDDOWN(F6,2) -> 0.13
A7: TK1401 | B7: BENDING | C7: 2800 | D7: =_xlfn.XLOOKUP(A7, produk!$B:$B, produk!$A:$A) -> 1 | E7: =_xlfn.XLOOKUP(B7, jenis_pekerjaan!$B:$B, jenis_pekerjaan!$A:$A) -> 20 | F7: 0.135 | G7: =ROUNDDOWN(F7,2) -> 0.13
A8: TK1401 | B8: ROUGHING | C8: 1000 | D8: =_xlfn.XLOOKUP(A8, produk!$B:$B, produk!$A:$A) -> 1 | E8: =_xlfn.XLOOKUP(B8, jenis_pekerjaan!$B:$B, jenis_pekerjaan!$A:$A) -> 71 | F8: 0.378 | G8: =ROUNDDOWN(F8,2) -> 0.37
D9: =_xlfn.XLOOKUP(A9, produk!$B:$B, produk!$A:$A) -> 0 | E9: =_xlfn.XLOOKUP(B9, jenis_pekerjaan!$B:$B, jenis_pekerjaan!$A:$A) -> 0 | G9: =ROUNDDOWN(F9,2) -> 0
A10: TK1403 | B10: PRESS | C10: 4500 | D10: =_xlfn.XLOOKUP(A10, produk!$B:$B, produk!$A:$A) -> 2 | E10: =_xlfn.XLOOKUP(B10, jenis_pekerjaan!$B:$B, jenis_pekerjaan!$A:$A) -> 1 | F10: 0.084 | G10: =ROUNDDOWN(F10,2) -> 0.08
A11: TK1403 | B11: SANDER | C11: 6300 | D11: =_xlfn.XLOOKUP(A11, produk!$B:$B, produk!$A:$A) -> 2 | E11: =_xlfn.XLOOKUP(B11, jenis_pekerjaan!$B:$B, jenis_pekerjaan!$A:$A) -> 2 | F11: 0.06 | G11: =ROUNDDOWN(F11,2) -> 0.06
D12: =_xlfn.XLOOKUP(A12, produk!$B:$B, produk!$A:$A) -> 0 | E12: =_xlfn.XLOOKUP(B12, jenis_pekerjaan!$B:$B, jenis_pekerjaan!$A:$A) -> 0 | G12: =ROUNDDOWN(F12,2) -> 0
A13: TK1608 | B13: PRESS | C13: 2100 | D13: =_xlfn.XLOOKUP(A13, produk!$B:$B, produk!$A:$A) -> 3 | E13: =_xlfn.XLOOKUP(B13, jenis_pekerjaan!$B:$B, jenis_pekerjaan!$A:$A) -> 1 | F13: 0.18 | G13: =ROUNDDOWN(F13,2) -> 0.18
D14: =_xlfn.XLOOKUP(A14, produk!$B:$B, produk!$A:$A) -> 0 | E14: =_xlfn.XLOOKUP(B14, jenis_pekerjaan!$B:$B, jenis_pekerjaan!$A:$A) -> 0 | G14: =ROUNDDOWN(F14,2) -> 0
A15: TK1609 | B15: PRESS | C15: 3500 | D15: =_xlfn.XLOOKUP(A15, produk!$B:$B, produk!$A:$A) -> 4 | E15: =_xlfn.XLOOKUP(B15, jenis_pekerjaan!$B:$B, jenis_pekerjaan!$A:$A) -> 1 | F15: 0.108 | G15: =ROUNDDOWN(F15,2) -> 0.1
A16: TK1609 | B16: SANDER | C16: 4000 | D16: =_xlfn.XLOOKUP(A16, produk!$B:$B, produk!$A:$A) -> 4 | E16: =_xlfn.XLOOKUP(B16, jenis_pekerjaan!$B:$B, jenis_pekerjaan!$A:$A) -> 2 | F16: 0.0945 | G16: =ROUNDDOWN(F16,2) -> 0.09
A17: TK1609 | B17: BUBUT | C17: 700 | D17: =_xlfn.XLOOKUP(A17, produk!$B:$B, produk!$A:$A) -> 4 | E17: =_xlfn.XLOOKUP(B17, jenis_pekerjaan!$B:$B, jenis_pekerjaan!$A:$A) -> 16 | F17: 0.54 | G17: =ROUNDDOWN(F17,2) -> 0.54
D18: =_xlfn.XLOOKUP(A18, produk!$B:$B, produk!$A:$A) -> 0 | E18: =_xlfn.XLOOKUP(B18, jenis_pekerjaan!$B:$B, jenis_pekerjaan!$A:$A) -> 0 | G18: =ROUNDDOWN(F18,2) -> 0
A19: TK4909 | B19: PRESS | D19: =_xlfn.XLOOKUP(A19, produk!$B:$B, produk!$A:$A) -> 5 | E19: =_xlfn.XLOOKUP(B19, jenis_pekerjaan!$B:$B, jenis_pekerjaan!$A:$A) -> 1 | F19: #DIV/0! | G19: =ROUNDDOWN(F19,2) -> #VALUE!
A20: TK4909 | B20: SANDER | D20: =_xlfn.XLOOKUP(A20, produk!$B:$B, produk!$A:$A) -> 5 | E20: =_xlfn.XLOOKUP(B20, jenis_pekerjaan!$B:$B, jenis_pekerjaan!$A:$A) -> 2 | F20: #DIV/0! | G20: =ROUNDDOWN(F20,2) -> #VALUE!
D21: =_xlfn.XLOOKUP(A21, produk!$B:$B, produk!$A:$A) -> 0 | E21: =_xlfn.XLOOKUP(B21, jenis_pekerjaan!$B:$B, jenis_pekerjaan!$A:$A) -> 0 | G21: =ROUNDDOWN(F21,2) -> 0
A22: TK5030 | B22: PRESS | C22: A160 | D22: =_xlfn.XLOOKUP(A22, produk!$B:$B, produk!$A:$A) -> 6 | E22: =_xlfn.XLOOKUP(B22, jenis_pekerjaan!$B:$B, jenis_pekerjaan!$A:$A) -> 1 | F22: 0.0252 | G22: =ROUNDDOWN(F22,2) -> 0.02
A23: TK5030 | B23: BARREL | C23: 0 | D23: =_xlfn.XLOOKUP(A23, produk!$B:$B, produk!$A:$A) -> 6 | E23: =_xlfn.XLOOKUP(B23, jenis_pekerjaan!$B:$B, jenis_pekerjaan!$A:$A) -> 55 | F23: #DIV/0! | G23: =ROUNDDOWN(F23,2) -> #VALUE!
D24: =_xlfn.XLOOKUP(A24, produk!$B:$B, produk!$A:$A) -> 0 | E24: =_xlfn.XLOOKUP(B24, jenis_pekerjaan!$B:$B, jenis_pekerjaan!$A:$A) -> 0 | G24: =ROUNDDOWN(F24,2) -> 0
A25: TK5037 | B25: PRESS | C25: 3780 | D25: =_xlfn.XLOOKUP(A25, produk!$B:$B, produk!$A:$A) -> 7 | E25: =_xlfn.XLOOKUP(B25, jenis_pekerjaan!$B:$B, jenis_pekerjaan!$A:$A) -> 1 | F25: 0,06 | G25: =ROUNDDOWN(F25,2) -> 0.06
A26: TK5037 | B26: SANDER | C26: 4000 | D26: =_xlfn.XLOOKUP(A26, produk!$B:$B, produk!$A:$A) -> 7 | E26: =_xlfn.XLOOKUP(B26, jenis_pekerjaan!$B:$B, jenis_pekerjaan!$A:$A) -> 2 | F26: 0.0945 | G26: =ROUNDDOWN(F26,2) -> 0.09
D27: =_xlfn.XLOOKUP(A27, produk!$B:$B, produk!$A:$A) -> 0 | E27: =_xlfn.XLOOKUP(B27, jenis_pekerjaan!$B:$B, jenis_pekerjaan!$A:$A) -> 0 | G27: =ROUNDDOWN(F27,2) -> 0
A28: TK5041 | B28: PRESS | C28: 3400 | D28: =_xlfn.XLOOKUP(A28, produk!$B:$B, produk!$A:$A) -> 8 | E28: =_xlfn.XLOOKUP(B28, jenis_pekerjaan!$B:$B, jenis_pekerjaan!$A:$A) -> 1 | F28: 0,11 | G28: =ROUNDDOWN(F28,2) -> 0.11
A29: TK5041 | B29: SANDER | C29: 3200 | D29: =_xlfn.XLOOKUP(A29, produk!$B:$B, produk!$A:$A) -> 8 | E29: =_xlfn.XLOOKUP(B29, jenis_pekerjaan!$B:$B, jenis_pekerjaan!$A:$A) -> 2 | F29: 0.118125 | G29: =ROUNDDOWN(F29,2) -> 0.11
D30: =_xlfn.XLOOKUP(A30, produk!$B:$B, produk!$A:$A) -> 0 | E30: =_xlfn.XLOOKUP(B30, jenis_pekerjaan!$B:$B, jenis_pekerjaan!$A:$A) -> 0 | G30: =ROUNDDOWN(F30,2) -> 0
A31: TK5047 | B31: PRESS | C31: 2700 | D31: =_xlfn.XLOOKUP(A31, produk!$B:$B, produk!$A:$A) -> 9 | E31: =_xlfn.XLOOKUP(B31, jenis_pekerjaan!$B:$B, jenis_pekerjaan!$A:$A) -> 1 | F31: 0,06 | G31: =ROUNDDOWN(F31,2) -> 0.06
A32: TK5047 | B32: SANDER | C32: 3500 | D32: =_xlfn.XLOOKUP(A32, produk!$B:$B, produk!$A:$A) -> 9 | E32: =_xlfn.XLOOKUP(B32, jenis_pekerjaan!$B:$B, jenis_pekerjaan!$A:$A) -> 2 | F32: 0.108 | G32: =ROUNDDOWN(F32,2) -> 0.1
A33: TK5047 | B33: SHAVING | C33: 2100 | D33: =_xlfn.XLOOKUP(A33, produk!$B:$B, produk!$A:$A) -> 9 | E33: =_xlfn.XLOOKUP(B33, jenis_pekerjaan!$B:$B, jenis_pekerjaan!$A:$A) -> 23 | F33: 0.18 | G33: =ROUNDDOWN(F33,2) -> 0.18
A34: TK5047 | B34: SANDER AS | C34: 4000 | D34: =_xlfn.XLOOKUP(A34, produk!$B:$B, produk!$A:$A) -> 9 | E34: =_xlfn.XLOOKUP(B34, jenis_pekerjaan!$B:$B, jenis_pekerjaan!$A:$A) -> 3 | F34: 0.0945 | G34: =ROUNDDOWN(F34,2) -> 0.09
D35: =_xlfn.XLOOKUP(A35, produk!$B:$B, produk!$A:$A) -> 0 | E35: =_xlfn.XLOOKUP(B35, jenis_pekerjaan!$B:$B, jenis_pekerjaan!$A:$A) -> 0 | G35: =ROUNDDOWN(F35,2) -> 0
A36: TK5063A | B36: PRESS | C36: 4900 | D36: =_xlfn.XLOOKUP(A36, produk!$B:$B, produk!$A:$A) -> 10 | E36: =_xlfn.XLOOKUP(B36, jenis_pekerjaan!$B:$B, jenis_pekerjaan!$A:$A) -> 1 | F36: 0,05 | G36: =ROUNDDOWN(F36,2) -> 0.05
A37: TK5063A | B37: SANDER | C37: 4900 | D37: =_xlfn.XLOOKUP(A37, produk!$B:$B, produk!$A:$A) -> 10 | E37: =_xlfn.XLOOKUP(B37, jenis_pekerjaan!$B:$B, jenis_pekerjaan!$A:$A) -> 2 | F37: 0.077142857 | G37: =ROUNDDOWN(F37,2) -> 0.07
A38: TK5063A | B38: BUBUT | C38: 1200 | D38: =_xlfn.XLOOKUP(A38, produk!$B:$B, produk!$A:$A) -> 10 | E38: =_xlfn.XLOOKUP(B38, jenis_pekerjaan!$B:$B, jenis_pekerjaan!$A:$A) -> 16 | F38: 0.315 | G38: =ROUNDDOWN(F38,2) -> 0.31
A39: TK5063A | B39: BRUSH | D39: =_xlfn.XLOOKUP(A39, produk!$B:$B, produk!$A:$A) -> 10 | E39: =_xlfn.XLOOKUP(B39, jenis_pekerjaan!$B:$B, jenis_pekerjaan!$A:$A) -> 19 | F39: 0.21 | G39: =ROUNDDOWN(F39,2) -> 0.21
D40: =_xlfn.XLOOKUP(A40, produk!$B:$B, produk!$A:$A) -> 0 | E40: =_xlfn.XLOOKUP(B40, jenis_pekerjaan!$B:$B, jenis_pekerjaan!$A:$A) -> 0 | G40: =ROUNDDOWN(F40,2) -> 0
...
