Workbook

Sheet Operator
A1: nama | B1: password | C1: jenis operator / divisi | D1: Plant | E1: Line | F1: Foto | G1: fk_id_divisi | H1: NO. REG
A2: SUPERVISOR | B2: 123 | C2: SUPERVISOR | D2: 3 | E2: SUPERVISOR | G2: 18
A3: ADMIN | B3: 123 | C3: ADMIN | D3: 3 | E3: ADMIN | G3: =_xlfn.XLOOKUP(C3,'Master Divisi'!B:B,'Master Divisi'!A:A) -> 17
A4: MOH. NURUL | B4: 123 | C4: MANDOR | D4: 3 | E4: FINE BLANKING | F4: https://lh3.googleusercontent.com/d/1gAX-UvJRW6WWIUJNrgomFyf-jqHaBIii | G4: =_xlfn.XLOOKUP(C4,'Master Divisi'!B:B,'Master Divisi'!A:A) -> #N/A | H4: 17040094
A5: MUHAMMAD BAGUS PRASETYA | B5: 123 | C5: PRODUKSI | D5: 3 | E5: FINE BLANKING | F5: https://lh3.googleusercontent.com/d/1nfqVgTpIH6JVLz0r-GHpBjnkhK-EbQaS | G5: =_xlfn.XLOOKUP(C5,'Master Divisi'!B:B,'Master Divisi'!A:A) -> 1 | H5: 17090108
A6: LIA ANDI ASMARAYANA | B6: 123 | C6: PRODUKSI | D6: 3 | E6: FINE BLANKING | F6: https://lh3.googleusercontent.com/d/1NjilrjGhsRPvifxCFqA8w3jJYLCRGya6 | G6: =_xlfn.XLOOKUP(C6,'Master Divisi'!B:B,'Master Divisi'!A:A) -> 1 | H6: 17070101
A7: WIMPY ILYASA MANUS | B7: 123 | C7: PRODUKSI | D7: 3 | E7: FINE BLANKING | F7: https://lh3.googleusercontent.com/d/1rhkvKZtr3sh04Fuo69_sdrKgNu6YJgPQ | G7: =_xlfn.XLOOKUP(C7,'Master Divisi'!B:B,'Master Divisi'!A:A) -> 1 | H7: 17120110
A8: YASIN | B8: 123 | C8: PRODUKSI | D8: 3 | E8: FINE BLANKING | F8: https://lh3.googleusercontent.com/d/1vEjYR0vvtU5wFQPXpkH0MgUvflyNawhb | G8: =_xlfn.XLOOKUP(C8,'Master Divisi'!B:B,'Master Divisi'!A:A) -> 1 | H8: 18010115
A9: APRIYANTO | B9: 123 | C9: PRODUKSI | D9: 3 | E9: FOREMAN | F9: https://lh3.googleusercontent.com/d/1I8573dty0-4MFDOEEhbsj2BEGzIddRgE | G9: =_xlfn.XLOOKUP(C9,'Master Divisi'!B:B,'Master Divisi'!A:A) -> 1 | H9: 15040007
A10: DEDDY PRASETIYO | B10: 123 | C10: PRODUKSI | D10: 3 | E10: FOREMAN | F10: https://lh3.googleusercontent.com/d/1Yg4nIzyWbuMVfEgmdwbM2MT4kwrgdKXQ | G10: =_xlfn.XLOOKUP(C10,'Master Divisi'!B:B,'Master Divisi'!A:A) -> 1 | H10: 15110016
A11: MUSTADO FEBRI UTOMO | B11: 123 | C11: PRODUKSI | D11: 3 | E11: PROGRESSIVE & TRANSFER | F11: https://lh3.googleusercontent.com/d/1tSa6SbR3CJBcjFKtGyx8-IxAAISuLWJ0 | G11: =_xlfn.XLOOKUP(C11,'Master Divisi'!B:B,'Master Divisi'!A:A) -> 1 | H11: 17020018
A12: IMAM SUDRAJAT | B12: 123 | C12: PRODUKSI | D12: 3 | E12: PROGRESSIVE & TRANSFER | F12: https://lh3.googleusercontent.com/d/1P4Hf1TdpQYKdZuZ6nO4EyIiDNU5AI4Cn | G12: =_xlfn.XLOOKUP(C12,'Master Divisi'!B:B,'Master Divisi'!A:A) -> 1 | H12: 17090023
A13: IMAM SUPRIADI | B13: 123 | C13: PRODUKSI | D13: 3 | E13: PROGRESSIVE & TRANSFER | F13: https://lh3.googleusercontent.com/d/1FDDws3I-3QQG_uuCTWAZ4SIVUiJRfmNC | G13: =_xlfn.XLOOKUP(C13,'Master Divisi'!B:B,'Master Divisi'!A:A) -> 1 | H13: 17090024
A14: MOCH. RIZKIAWAN | B14: 123 | C14: PRODUKSI | D14: 3 | E14: PROGRESSIVE & TRANSFER | F14: https://lh3.googleusercontent.com/d/1LkKlxxsfGbT1YSTU-cu-HARsEkJX3k2B | G14: =_xlfn.XLOOKUP(C14,'Master Divisi'!B:B,'Master Divisi'!A:A) -> 1 | H14: 18010027
A15: RIFQI FIRMAN KHAKIKI | B15: 123 | C15: PRODUKSI | D15: 3 | E15: SECONDARY | F15: https://lh3.googleusercontent.com/d/1UM0G9yNYT8BX66mNC1x68MZcO40b9Fw7 | G15: =_xlfn.XLOOKUP(C15,'Master Divisi'!B:B,'Master Divisi'!A:A) -> 1 | H15: 18050030
... A19: MUHAMMAD RIZAL ARDIANSYAH | B19: 123 | C19: PRODUKSI | D19: 3 | E19: SECONDARY | F19: https://lh3.googleusercontent.com/d/1dxnETEZQIZXZmd1K91NgG24RjBPB13gi | G19: =_xlfn.XLOOKUP(C19,'Master Divisi'!B:B,'Master Divisi'!A:A) -> 1 | H19: 21010198
A20: RUDI SEPTYAN | B20: 123 | C20: PRODUKSI | D20: 3 | E20: SECONDARY | F20: https://lh3.googleusercontent.com/d/1yzV_ZDNpPdFUzV2tGcSaMwnSfN98wbM- | G20: =_xlfn.XLOOKUP(C20,'Master Divisi'!B:B,'Master Divisi'!A:A) -> 1 | H20: 21030202
A21: ABRILLYANT LINTANG KRESNAYA | B21: 123 | C21: PRODUKSI | D21: 3 | E21: SECONDARY | F21: https://lh3.googleusercontent.com/d/14MQbFGVgT621Jw3rCnyyGEKfriJS6bmH | G21: =_xlfn.XLOOKUP(C21,'Master Divisi'!B:B,'Master Divisi'!A:A) -> 1 | H21: 21030203
A22: ADE SULISTYA PUTRA | B22: 123 | C22: PRODUKSI | D22: 3 | E22: SECONDARY | F22: https://lh3.googleusercontent.com/d/1atulX3uV3uYF8YQN7Zao8uDSflC0PXQB | G22: =_xlfn.XLOOKUP(C22,'Master Divisi'!B:B,'Master Divisi'!A:A) -> 1 | H22: 21040210
A23: SAHRUL AFANDI | B23: 123 | C23: PRODUKSI | D23: 3 | E23: SECONDARY | F23: https://lh3.googleusercontent.com/d/1RKRTPGDE4WeWtiJtswfxwWX7CIto3JgX | G23: =_xlfn.XLOOKUP(C23,'Master Divisi'!B:B,'Master Divisi'!A:A) -> 1 | H23: 21040211
A24: ANNAS FADLOLI | B24: 123 | C24: PRODUKSI | D24: 3 | E24: SECONDARY | F24: https://lh3.googleusercontent.com/d/1l7PYgr1RnzEHF2iwDC2_TMytttzPiLuc | G24: =_xlfn.XLOOKUP(C24,'Master Divisi'!B:B,'Master Divisi'!A:A) -> 1 | H24: 21040212
A25: HASBY SURYA SYAHPUTRA | B25: 123 | C25: PRODUKSI | D25: 3 | E25: SECONDARY | F25: https://lh3.googleusercontent.com/d/1NxA9GTWAQSuG8pXAUZtEdohTXdXAg4XS | G25: =_xlfn.XLOOKUP(C25,'Master Divisi'!B:B,'Master Divisi'!A:A) -> 1 | H25: 21040216
A26: ADITYA WIJAYA | B26: 123 | C26: PRODUKSI | D26: 3 | E26: SECONDARY | F26: https://lh3.googleusercontent.com/d/1LM417YcHesASAJgxWAHSR2u9Bk1Le-Ac | G26: =_xlfn.XLOOKUP(C26,'Master Divisi'!B:B,'Master Divisi'!A:A) -> 1 | H26: 21050217
A27: MUHAMMAD HANDI RISKIANTO | B27: 123 | C27: PRODUKSI | D27: 3 | E27: SECONDARY | F27: https://lh3.googleusercontent.com/d/1o7n2Pessp4tfGXTHjLfhTZdPSp2qa0VH | G27: =_xlfn.XLOOKUP(C27,'Master Divisi'!B:B,'Master Divisi'!A:A) -> 1 | H27: 21050218
A28: MOCHAMMAD NIZAR | B28: 123 | C28: PRODUKSI | D28: 3 | E28: SECONDARY | F28: https://lh3.googleusercontent.com/d/1InnwtM6-86T7lBeh21WtnBqkrKm2pmO3 | G28: =_xlfn.XLOOKUP(C28,'Master Divisi'!B:B,'Master Divisi'!A:A) -> 1 | H28: 21060220
A29: IMAM ZAKARIA | B29: 123 | C29: PRODUKSI | D29: 3 | E29: SECONDARY | F29: https://lh3.googleusercontent.com/d/1mnCcPrgyDQQkIOfhhQZNII9UfA3NaviG | G29: =_xlfn.XLOOKUP(C29,'Master Divisi'!B:B,'Master Divisi'!A:A) -> 1 | H29: 21060222
A30: ARIS SETYAWAN | B30: 123 | C30: PRODUKSI | D30: 3 | E30: SECONDARY | F30: https://lh3.googleusercontent.com/d/1lEx8lqkmwM1XRAOvAjM8TpRKKiJ-V7Hu | G30: =_xlfn.XLOOKUP(C30,'Master Divisi'!B:B,'Master Divisi'!A:A) -> 1 | H30: 21090223
A31: OCTAVIO VALENTINO FERARRI | B31: 123 | C31: PRODUKSI | D31: 3 | E31: SECONDARY | F31: https://lh3.googleusercontent.com/d/1lMpx_-a4Gcq7InNjuQvTLG29eDtLF0Qg | G31: =_xlfn.XLOOKUP(C31,'Master Divisi'!B:B,'Master Divisi'!A:A) -> 1 | H31: 21100226
A32: AKHMAD NAUFAL | B32: 123 | C32: PRODUKSI | D32: 3 | E32: SECONDARY | F32: https://lh3.googleusercontent.com/d/1fIDgWTzL4HwjUlv6OKxBtB5VLqtoI60t | G32: =_xlfn.XLOOKUP(C32,'Master Divisi'!B:B,'Master Divisi'!A:A) -> 1 | H32: 22010229
... A88: CHOIRUL ANAM | B88: 123 | C88: PRODUKSI | D88: 3 | E88: SECONDARY | F88: https://lh3.googleusercontent.com/d/ | G88: =_xlfn.XLOOKUP(C88,'Master Divisi'!B:B,'Master Divisi'!A:A) -> 1 | H88: 25100345
A89: ARIF TRI AFANDI | B89: 123 | C89: QUALITY | D89: 3 | E89: QUALITY | G89: =_xlfn.XLOOKUP(C89,'Master Divisi'!B:B,'Master Divisi'!A:A) -> 2
A90: DIMAS RIZKY | B90: 123 | C90: QUALITY | D90: 3 | E90: QUALITY | G90: =_xlfn.XLOOKUP(C90,'Master Divisi'!B:B,'Master Divisi'!A:A) -> 2
A91: DICKY YUSUF | B91: 123 | C91: QUALITY | D91: 3 | E91: QUALITY | G91: =_xlfn.XLOOKUP(C91,'Master Divisi'!B:B,'Master Divisi'!A:A) -> 2
A92: ARDI BAGAS SETIAWAN | B92: 123 | C92: QUALITY | D92: 3 | E92: QUALITY | G92: =_xlfn.XLOOKUP(C92,'Master Divisi'!B:B,'Master Divisi'!A:A) -> 2
A93: CAHYO MULYO | B93: 123 | C93: QUALITY | D93: 3 | E93: QUALITY | G93: =_xlfn.XLOOKUP(C93,'Master Divisi'!B:B,'Master Divisi'!A:A) -> 2
A94: JOHAN PUTRO PRIBADI | B94: 123 | C94: QUALITY | D94: 3 | E94: QUALITY | G94: =_xlfn.XLOOKUP(C94,'Master Divisi'!B:B,'Master Divisi'!A:A) -> 2
A95: ACHMAD SUBAKRI | B95: 123 | C95: QUALITY | D95: 3 | E95: QUALITY | G95: =_xlfn.XLOOKUP(C95,'Master Divisi'!B:B,'Master Divisi'!A:A) -> 2
A96: ELVAN PRAMBUDI SAPUTRA | B96: 123 | C96: QUALITY | D96: 3 | E96: QUALITY | G96: =_xlfn.XLOOKUP(C96,'Master Divisi'!B:B,'Master Divisi'!A:A) -> 2
A97: DAFA NAYAKA ENRICO | B97: 123 | C97: QUALITY | D97: 3 | E97: QUALITY | G97: =_xlfn.XLOOKUP(C97,'Master Divisi'!B:B,'Master Divisi'!A:A) -> 2
A98: DAINUR ROHMAN | B98: 123 | C98: QUALITY | D98: 3 | E98: QUALITY | G98: =_xlfn.XLOOKUP(C98,'Master Divisi'!B:B,'Master Divisi'!A:A) -> 2
...

Sheet Master Divisi
A1: id | B1: PRODUKSI
A2: =ROW()-1 -> 1 | B2: PRODUKSI
A3: =ROW()-1 -> 2 | B3: QUALITY
A4: =ROW()-1 -> 3 | B4: MAINTENANCE
A5: =ROW()-1 -> 4 | B5: DIE_MAINT
A6: =ROW()-1 -> 5 | B6: ENGINEERING
A7: =ROW()-1 -> 6 | B7: MARKETING
A8: =ROW()-1 -> 7 | B8: COMMERCIAL
A9: =ROW()-1 -> 8 | B9: PPIC
A10: =ROW()-1 -> 9 | B10: HCPGA
A11: =ROW()-1 -> 10 | B11: WRH_CIBITUNG
A12: =ROW()-1 -> 11 | B12: GA
A13: =ROW()-1 -> 12 | B13: WAREHOUSE
... A18: =ROW()-1 -> 17 | B18: ADMIN
A19: 18 | B19: SUPERVISOR
